Workbook

Sheet Rates
A1: Discipline rates & assumptions
A3: Discipline | B3: Day rate (AUD) | C3: Hourly (AUD)
A4: Design / UX | B4: 900 | C4: =B4/$B$9
A5: Frontend (React/Next) | B5: 1000 | C5: =B5/$B$9
A6: Backend | B6: 1050 | C6: =B6/$B$9
A7: DevOps / Infra | B7: 1150 | C7: =B7/$B$9
A8: PM / BA / Admin | B8: 850 | C8: =B8/$B$9
A9: Hours per day | B9: 8
A11: Note
A12: AU FY25/26 market contract rates, billed direct as a company (ex-GST; add 10% on invoice). Edit the day rates above — every figure in the Items and Summary sheets recalculates. Hours assume one specialist per discipline working in parallel.

Sheet Items
A1: Item | B1: Section | C1: Feature | D1: Scope | E1: Status | F1: Design h | G1: Frontend h | H1: Backend h | I1: DevOps h | J1: PM/Admin h | K1: Total h | L1: Cost (AUD) | M1: Notes
A2: 1 | B2: A. Admin — Home / Dashboard | C2: Admin landing / dashboard (to be replaced) | D2: Done/— | E2: EXISTS | F2: 0 | G2: 0 | H2: 0 | I2: 0 | J2: 0 | K2: =SUM(F2:J2) | L2: =F2*Rates!$B$4/Rates!$B$9+G2*Rates!$B$5/Rates!$B$9+H2*Rates!$B$6/Rates!$B$9+I2*Rates!$B$7/Rates!$B$9+J2*Rates!$B$8/Rates!$B$9
A3: 2 | B3: A. Admin — Home / Dashboard | C3: Total Schools vs Active (onboarding-complete) Schools | D3: Additional | E3: PARTIAL | F3: 3 | G3: 8 | H3: 10 | I3: 0 | J3: 2 | K3: =SUM(F3:J3) | L3: =F3*Rates!$B$4/Rates!$B$9+G3*Rates!$B$5/Rates!$B$9+H3*Rates!$B$6/Rates!$B$9+I3*Rates!$B$7/Rates!$B$9+J3*Rates!$B$8/Rates!$B$9
A4: 3 | B4: A. Admin — Home / Dashboard | C4: Per-school schedule status (On / Ahead / Slightly Behind / Behind) | D4: Additional | E4: MISSING | F4: 8 | G4: 20 | H4: 30 | I4: 4 | J4: 8 | K4: =SUM(F4:J4) | L4: =F4*Rates!$B$4/Rates!$B$9+G4*Rates!$B$5/Rates!$B$9+H4*Rates!$B$6/Rates!$B$9+I4*Rates!$B$7/Rates!$B$9+J4*Rates!$B$8/Rates!$B$9
A5: 4 | B5: A. Admin — Home / Dashboard | C5: “This School Year” / program-year selector (multi-year) | D5: Additional | E5: MISSING | F5: 4 | G5: 16 | H5: 16 | I5: 0 | J5: 4 | K5: =SUM(F5:J5) | L5: =F5*Rates!$B$4/Rates!$B$9+G5*Rates!$B$5/Rates!$B$9+H5*Rates!$B$6/Rates!$B$9+I5*Rates!$B$7/Rates!$B$9+J5*Rates!$B$8/Rates!$B$9
A6: 5 | B6: A. Admin — Home / Dashboard | C6: Data model: each school’s initial year vs ongoing years | D6: Additional | E6: MISSING | F6: 2 | G6: 4 | H6: 40 | I6: 6 | J6: 6 | K6: =SUM(F6:J6) | L6: =F6*Rates!$B$4/Rates!$B$9+G6*Rates!$B$5/Rates!$B$9+H6*Rates!$B$6/Rates!$B$9+I6*Rates!$B$7/Rates!$B$9+J6*Rates!$B$8/Rates!$B$9
A7: 6 | B7: A. Admin — Home / Dashboard | C7: Sidebar items: Manage Schools / Lessons / AP Cert / Users | D7: Additional | E7: EXISTS | F7: 0 | G7: 5 | H7: 0 | I7: 0 | J7: 1 | K7: =SUM(F7:J7) | L7: =F7*Rates!$B$4/Rates!$B$9+G7*Rates!$B$5/Rates!$B$9+H7*Rates!$B$6/Rates!$B$9+I7*Rates!$B$7/Rates!$B$9+J7*Rates!$B$8/Rates!$B$9
A8: 7 | B8: A. Admin — Home / Dashboard | C8: Dashboard filters: state, school level, sector, AP level, status | D8: Additional | E8: PARTIAL | F8: 3 | G8: 14 | H8: 6 | I8: 0 | J8: 2 | K8: =SUM(F8:J8) | L8: =F8*Rates!$B$4/Rates!$B$9+G8*Rates!$B$5/Rates!$B$9+H8*Rates!$B$6/Rates!$B$9+I8*Rates!$B$7/Rates!$B$9+J8*Rates!$B$8/Rates!$B$9
A9: 8 | B9: A. Admin — Home / Dashboard | C9: Dashboard columns (Culture trend, AP Cert %, Students, Classes, Teacher History, Lessons %, Schedule, Last Activity, Action) | D9: Additional | E9: PARTIAL | F9: 6 | G9: 28 | H9: 30 | I9: 0 | J9: 6 | K9: =SUM(F9:J9) | L9: =F9*Rates!$B$4/Rates!$B$9+G9*Rates!$B$5/Rates!$B$9+H9*Rates!$B$6/Rates!$B$9+I9*Rates!$B$7/Rates!$B$9+J9*Rates!$B$8/Rates!$B$9
A10: 9 | B10: A. Admin — Home / Dashboard | C10: Drill-downs: Onboarding, Culture, AP Cert detail, Class, Lesson History, Teacher History | D10: Additional | E10: PARTIAL | F10: 8 | G10: 28 | H10: 28 | I10: 0 | J10: 6 | K10: =SUM(F10:J10) | L10: =F10*Rates!$B$4/Rates!$B$9+G10*Rates!$B$5/Rates!$B$9+H10*Rates!$B$6/Rates!$B$9+I10*Rates!$B$7/Rates!$B$9+J10*Rates!$B$8/Rates!$B$9
A11: 10 | B11: B. School Terms / Schedule Engine | C11: Settings → School Terms (per-state term dates, per year, annual reset) | D11: Additional | E11: MISSING | F11: 4 | G11: 16 | H11: 20 | I11: 4 | J11: 4 | K11: =SUM(F11:J11) | L11: =F11*Rates!$B$4/Rates!$B$9+G11*Rates!$B$5/Rates!$B$9+H11*Rates!$B$6/Rates!$B$9+I11*Rates!$B$7/Rates!$B$9+J11*Rates!$B$8/Rates!$B$9
A12: 11 | B12: B. School Terms / Schedule Engine | C12: Term entry form (year/state/term dropdowns, date pickers, end-before-start validation) | D12: Additional | E12: MISSING | F12: 3 | G12: 14 | H12: 6 | I12: 0 | J12: 2 | K12: =SUM(F12:J12) | L12: =F12*Rates!$B$4/Rates!$B$9+G12*Rates!$B$5/Rates!$B$9+H12*Rates!$B$6/Rates!$B$9+I12*Rates!$B$7/Rates!$B$9+J12*Rates!$B$8/Rates!$B$9
A13: 12 | B13: B. School Terms / Schedule Engine | C13: Schedule calculation engine (progress vs Term 2 cadence, by state terms) | D13: Additional | E13: MISSING | F13: 2 | G13: 6 | H13: 60 | I13: 6 | J13: 8 | K13: =SUM(F13:J13) | L13: =F13*Rates!$B$4/Rates!$B$9+G13*Rates!$B$5/Rates!$B$9+H13*Rates!$B$6/Rates!$B$9+I13*Rates!$B$7/Rates!$B$9+J13*Rates!$B$8/Rates!$B$9
... A18: 17 | B18: C. Culture Rating | C18: UX: comparative-period dropdown + speedometer (±100%, expandable to 150/200%) | D18: Additional | E18: PARTIAL | F18: 8 | G18: 14 | H18: 2 | I18: 0 | J18: 1 | K18: =SUM(F18:J18) | L18: =F18*Rates!$B$4/Rates!$B$9+G18*Rates!$B$5/Rates!$B$9+H18*Rates!$B$6/Rates!$B$9+I18*Rates!$B$7/Rates!$B$9+J18*Rates!$B$8/Rates!$B$9
A19: 18 | B19: D. Content Types (Multi-Curriculum) | C19: Add new Content Types / curricula (name, level count, level names) | D19: Original | E19: MISSING | F19: 8 | G19: 28 | H19: 36 | I19: 4 | J19: 8 | K19: =SUM(F19:J19) | L19: =F19*Rates!$B$4/Rates!$B$9+G19*Rates!$B$5/Rates!$B$9+H19*Rates!$B$6/Rates!$B$9+I19*Rates!$B$7/Rates!$B$9+J19*Rates!$B$8/Rates!$B$9 | M19: Agreed price $30,000 (value-priced; ~$10,550 at cost)
A20: 19 | B20: D. Content Types (Multi-Curriculum) | C20: Per-content-type lesson creation / upload | D20: Additional | E20: PARTIAL | F20: 4 | G20: 24 | H20: 16 | I20: 0 | J20: 4 | K20: =SUM(F20:J20) | L20: =F20*Rates!$B$4/Rates!$B$9+G20*Rates!$B$5/Rates!$B$9+H20*Rates!$B$6/Rates!$B$9+I20*Rates!$B$7/Rates!$B$9+J20*Rates!$B$8/Rates!$B$9
A21: 20 | B21: D. Content Types (Multi-Curriculum) | C21: Content Type dropdown on Add New School | D21: Additional | E21: MISSING | F21: 2 | G21: 10 | H21: 8 | I21: 0 | J21: 2 | K21: =SUM(F21:J21) | L21: =F21*Rates!$B$4/Rates!$B$9+G21*Rates!$B$5/Rates!$B$9+H21*Rates!$B$6/Rates!$B$9+I21*Rates!$B$7/Rates!$B$9+J21*Rates!$B$8/Rates!$B$9
A22: 21 | B22: D. Content Types (Multi-Curriculum) | C22: Per-content-type resources | D22: Additional | E22: PARTIAL | F22: 2 | G22: 8 | H22: 12 | I22: 0 | J22: 2 | K22: =SUM(F22:J22) | L22: =F22*Rates!$B$4/Rates!$B$9+G22*Rates!$B$5/Rates!$B$9+H22*Rates!$B$6/Rates!$B$9+I22*Rates!$B$7/Rates!$B$9+J22*Rates!$B$8/Rates!$B$9
A23: 22 | B23: E. Content Management / Security | C23: MFA on content edits (email verification code before saving) | D23: Additional | E23: MISSING | F23: 0 | G23: 6 | H23: 16 | I23: 2 | J23: 2 | K23: =SUM(F23:J23) | L23: =F23*Rates!$B$4/Rates!$B$9+G23*Rates!$B$5/Rates!$B$9+H23*Rates!$B$6/Rates!$B$9+I23*Rates!$B$7/Rates!$B$9+J23*Rates!$B$8/Rates!$B$9
A24: 23 | B24: E. Content Management / Security | C24: Sole-content-editor / content-edit permission model | D24: Additional | E24: PARTIAL | F24: 0 | G24: 6 | H24: 12 | I24: 0 | J24: 2 | K24: =SUM(F24:J24) | L24: =F24*Rates!$B$4/Rates!$B$9+G24*Rates!$B$5/Rates!$B$9+H24*Rates!$B$6/Rates!$B$9+I24*Rates!$B$7/Rates!$B$9+J24*Rates!$B$8/Rates!$B$9
A25: 24 | B25: E. Content Management / Security | C25: Content audit log (create/edit/delete; date, user, event, content, version; comments) | D25: Additional | E25: MISSING | F25: 2 | G25: 14 | H25: 28 | I25: 0 | J25: 4 | K25: =SUM(F25:J25) | L25: =F25*Rates!$B$4/Rates!$B$9+G25*Rates!$B$5/Rates!$B$9+H25*Rates!$B$6/Rates!$B$9+I25*Rates!$B$7/Rates!$B$9+J25*Rates!$B$8/Rates!$B$9
A26: 25 | B26: E. Content Management / Security | C26: Version numbers + last-updated/updated-by per lesson/module; report; read-only retention | D26: Additional | E26: MISSING | F26: 0 | G26: 12 | H26: 30 | I26: 2 | J26: 4 | K26: =SUM(F26:J26) | L26: =F26*Rates!$B$4/Rates!$B$9+G26*Rates!$B$5/Rates!$B$9+H26*Rates!$B$6/Rates!$B$9+I26*Rates!$B$7/Rates!$B$9+J26*Rates!$B$8/Rates!$B$9
A27: 26 | B27: F. Getting Started Videos | C27: Role-based getting-started videos (autoplay first login, sidebar replay, add/replace) | D27: Additional | E27: PARTIAL | F27: 6 | G27: 18 | H27: 16 | I27: 2 | J27: 6 | K27: =SUM(F27:J27) | L27: =F27*Rates!$B$4/Rates!$B$9+G27*Rates!$B$5/Rates!$B$9+H27*Rates!$B$6/Rates!$B$9+I27*Rates!$B$7/Rates!$B$9+J27*Rates!$B$8/Rates!$B$9
A28: 27 | B28: G. Add New School | C28: “Other” school level allowing arbitrary grade mixes (P-7, P-8) | D28: Additional | E28: MISSING | F28: 2 | G28: 8 | H28: 12 | I28: 0 | J28: 3 | K28: =SUM(F28:J28) | L28: =F28*Rates!$B$4/Rates!$B$9+G28*Rates!$B$5/Rates!$B$9+H28*Rates!$B$6/Rates!$B$9+I28*Rates!$B$7/Rates!$B$9+J28*Rates!$B$8/Rates!$B$9
A29: 28 | B29: H. Roles / Access Levels | C29: Rename “Roles” → “Access Levels” throughout; show only highest level per user | D29: Additional | E29: MISSING | F29: 2 | G29: 14 | H29: 6 | I29: 0 | J29: 3 | K29: =SUM(F29:J29) | L29: =F29*Rates!$B$4/Rates!$B$9+G29*Rates!$B$5/Rates!$B$9+H29*Rates!$B$6/Rates!$B$9+I29*Rates!$B$7/Rates!$B$9+J29*Rates!$B$8/Rates!$B$9
A30: 29 | B30: H. Roles / Access Levels | C30: “Amayda” access tier above Bullyproof Admin | D30: Additional | E30: MISSING | F30: 2 | G30: 12 | H30: 28 | I30: 0 | J30: 6 | K30: =SUM(F30:J30) | L30: =F30*Rates!$B$4/Rates!$B$9+G30*Rates!$B$5/Rates!$B$9+H30*Rates!$B$6/Rates!$B$9+I30*Rates!$B$7/Rates!$B$9+J30*Rates!$B$8/Rates!$B$9
A31: 30 | B31: H. Roles / Access Levels | C31: School Licence account able to add/edit users (currently setup-only?) | D31: Additional | E31: PARTIAL | F31: 0 | G31: 5 | H31: 12 | I31: 0 | J31: 3 | K31: =SUM(F31:J31) | L31: =F31*Rates!$B$4/Rates!$B$9+G31*Rates!$B$5/Rates!$B$9+H31*Rates!$B$6/Rates!$B$9+I31*Rates!$B$7/Rates!$B$9+J31*Rates!$B$8/Rates!$B$9
A32: 31 | B32: I. Branding | C32: Logo/icon: BP → BA everywhere, animated logo, icon variants | D32: Goodwill | E32: PARTIAL | F32: 36 | G32: 30 | H32: 0 | I32: 6 | J32: 6 | K32: =SUM(F32:J32) | L32: 0 | M32: Goodwill - included at no charge (module M8; ~$9,300 of work, charged $0)
A33: 32 | B33: J. AP Certificate | C33: Certificate generation on course completion; accessible/downloadable | D33: Additional | E33: PARTIAL | F33: 4 | G33: 10 | H33: 8 | I33: 0 | J33: 2 | K33: =SUM(F33:J33) | L33: =F33*Rates!$B$4/Rates!$B$9+G33*Rates!$B$5/Rates!$B$9+H33*Rates!$B$6/Rates!$B$9+I33*Rates!$B$7/Rates!$B$9+J33*Rates!$B$8/Rates!$B$9
A34: 33 | B34: J. AP Certificate | C34: Uploadable/replaceable certificate template with fields (name, date, optional cert number) | D34: Additional | E34: MISSING | F34: 6 | G34: 16 | H34: 20 | I34: 2 | J34: 4 | K34: =SUM(F34:J34) | L34: =F34*Rates!$B$4/Rates!$B$9+G34*Rates!$B$5/Rates!$B$9+H34*Rates!$B$6/Rates!$B$9+I34*Rates!$B$7/Rates!$B$9+J34*Rates!$B$8/Rates!$B$9
A35: 34 | B35: K. Reports (Admin) | C35: Reports: School Status, Lesson Completion & Ratings, Culture Rating, AP Certification & Ratings | D35: Additional | E35: PARTIAL | F35: 2 | G35: 10 | H35: 10 | I35: 0 | J35: 3 | K35: =SUM(F35:J35) | L35: =F35*Rates!$B$4/Rates!$B$9+G35*Rates!$B$5/Rates!$B$9+H35*Rates!$B$6/Rates!$B$9+I35*Rates!$B$7/Rates!$B$9+J35*Rates!$B$8/Rates!$B$9
A36: 35 | B36: K. Reports (Admin) | C36: Per-report Filters panel + Export modal (CSV/Excel/PDF), export scope | D36: Additional | E36: MISSING | F36: 3 | G36: 18 | H36: 16 | I36: 0 | J36: 3 | K36: =SUM(F36:J36) | L36: =F36*Rates!$B$4/Rates!$B$9+G36*Rates!$B$5/Rates!$B$9+H36*Rates!$B$6/Rates!$B$9+I36*Rates!$B$7/Rates!$B$9+J36*Rates!$B$8/Rates!$B$9
A37: 36 | B37: K. Reports (Admin) | C37: Government stakeholder dashboards / reporting | D37: Additional | E37: MISSING | F37: 10 | G37: 28 | H37: 28 | I37: 0 | J37: 8 | K37: =SUM(F37:J37) | L37: =F37*Rates!$B$4/Rates!$B$9+G37*Rates!$B$5/Rates!$B$9+H37*Rates!$B$6/Rates!$B$9+I37*Rates!$B$7/Rates!$B$9+J37*Rates!$B$8/Rates!$B$9
A38: 37 | B38: K. Reports (Admin) | C38: Exclude “Bullyproof Academy” test school from reports | D38: Additional | E38: MISSING | F38: 0 | G38: 0 | H38: 5 | I38: 0 | J38: 1 | K38: =SUM(F38:J38) | L38: =F38*Rates!$B$4/Rates!$B$9+G38*Rates!$B$5/Rates!$B$9+H38*Rates!$B$6/Rates!$B$9+I38*Rates!$B$7/Rates!$B$9+J38*Rates!$B$8/Rates!$B$9
A39: 38 | B39: L. Onboarding | C39: Onboarding checklist: Benchmark received, Jeff Horn visit, Practical Training, Onboarding Session (dates + active/locked) | D39: Additional | E39: MISSING | F39: 4 | G39: 18 | H39: 20 | I39: 0 | J39: 6 | K39: =SUM(F39:J39) | L39: =F39*Rates!$B$4/Rates!$B$9+G39*Rates!$B$5/Rates!$B$9+H39*Rates!$B$6/Rates!$B$9+I39*Rates!$B$7/Rates!$B$9+J39*Rates!$B$8/Rates!$B$9
A40: 39 | B40: L. Onboarding | C40: (defect) School Address & Email Domain not saving on edit | D40: Original | E40: EXISTS | F40: 0 | G40: 1 | H40: 2 | I40: 0 | J40: 1 | K40: =SUM(F40:J40) | L40: =F40*Rates!$B$4/Rates!$B$9+G40*Rates!$B$5/Rates!$B$9+H40*Rates!$B$6/Rates!$B$9+I40*Rates!$B$7/Rates!$B$9+J40*Rates!$B$8/Rates!$B$9
A41: 40 | B41: L. Onboarding | C41: (defect/UX) Apply Template visual confirmation (Template Active / green) | D41: Original | E41: PARTIAL | F41: 3 | G41: 16 | H41: 4 | I41: 0 | J41: 2 | K41: =SUM(F41:J41) | L41: =F41*Rates!$B$4/Rates!$B$9+G41*Rates!$B$5/Rates!$B$9+H41*Rates!$B$6/Rates!$B$9+I41*Rates!$B$7/Rates!$B$9+J41*Rates!$B$8/Rates!$B$9
A42: 41 | B42: L. Onboarding | C42: (defect) Activity / Licence / Feature Access buttons non-functional | D42: Additional | E42: PARTIAL | F42: 3 | G42: 20 | H42: 28 | I42: 0 | J42: 4 | K42: =SUM(F42:J42) | L42: =F42*Rates!$B$4/Rates!$B$9+G42*Rates!$B$5/Rates!$B$9+H42*Rates!$B$6/Rates!$B$9+I42*Rates!$B$7/Rates!$B$9+J42*Rates!$B$8/Rates!$B$9
A43: 42 | B43: L. Onboarding | C43: Add Class: capture student numbers (Class Size field) | D43: Additional | E43: PARTIAL | F43: 0 | G43: 5 | H43: 2 | I43: 0 | J43: 1 | K43: =SUM(F43:J43) | L43: =F43*Rates!$B$4/Rates!$B$9+G43*Rates!$B$5/Rates!$B$9+H43*Rates!$B$6/Rates!$B$9+I43*Rates!$B$7/Rates!$B$9+J43*Rates!$B$8/Rates!$B$9
A44: 43 | B44: M. School Portal | C44: Remove Dashboard; role-based Home pages (Staff / AP Teacher / School Admin) | D44: Additional | E44: PARTIAL | F44: 4 | G44: 22 | H44: 6 | I44: 0 | J44: 3 | K44: =SUM(F44:J44) | L44: =F44*Rates!$B$4/Rates!$B$9+G44*Rates!$B$5/Rates!$B$9+H44*Rates!$B$6/Rates!$B$9+I44*Rates!$B$7/Rates!$B$9+J44*Rates!$B$8/Rates!$B$9
...

Sheet Summary
A1: Bullyproof — Change Request · Discipline costing
A3: By discipline
A4: Discipline | B4: Hours | C4: Day rate | D4: Days | E4: Cost (AUD)
A5: Design / UX | B5: =SUM(Items!F2:F61) | C5: =Rates!B4 | D5: =B5/Rates!$B$9 | E5: =D5*C5
A6: Frontend (React/Next) | B6: =SUM(Items!G2:G61) | C6: =Rates!B5 | D6: =B6/Rates!$B$9 | E6: =D6*C6
A7: Backend | B7: =SUM(Items!H2:H61) | C7: =Rates!B6 | D7: =B7/Rates!$B$9 | E7: =D7*C7
A8: DevOps / Infra | B8: =SUM(Items!I2:I61) | C8: =Rates!B7 | D8: =B8/Rates!$B$9 | E8: =D8*C8
A9: PM / BA / Admin | B9: =SUM(Items!J2:J61) | C9: =Rates!B8 | D9: =B9/Rates!$B$9 | E9: =D9*C9
A10: TOTAL | B10: =SUM(B5:B9) | D10: =SUM(D5:D9) | E10: =SUM(E5:E9)
A12: By scope
A13: Scope | B13: Items | C13: Hours | D13: Cost (AUD) | E13: Note
A14: Original agreement (content + bugs) | B14: =COUNTIF(Items!D2:D61,"Original") | C14: =SUMIF(Items!D2:D61,"Original",Items!K2:K61) | D14: =SUMIF(Items!D2:D61,"Original",Items!L2:L61) | E14: Committed ~6 weeks. Item 18 content type agreed at $30k.
A15: Additional scope (added later) | B15: =COUNTIF(Items!D2:D61,"Additional") | C15: =SUMIF(Items!D2:D61,"Additional",Items!K2:K61) | D15: =SUMIF(Items!D2:D61,"Additional",Items!L2:L61) | E15: Billed on top, own timeline.
A16: Goodwill - Brand Refresh (M8), no charge | B16: =COUNTIF(Items!D2:D61,"Goodwill") | C16: =SUMIF(Items!D2:D61,"Goodwill",Items!K2:K61) | D16: 0 | E16: Included free as a goodwill gesture; effort kept in the model but excluded from the chargeable total.
A17: CHARGEABLE total (man-hours, ex goodwill) | C17: =Items!K62 | D17: =Items!L62
